Workbook

Sheet Mesures
A1: Date | B1: Version | C1: Modification | D1: Reglages | E1: Lancements | F1: Cas | G1: Image (ms) | H1: img/s reelles | I1: GPU moyen (ms) | J1: GPU mediane (ms) | K1: Surfaces (ms) | L1: Fumee (ms) | M1: Reflet sol (ms) | N1: Paires d'ombre | O1: Dossiers | P1: Lasers (ms) | Q1: Banc
A2: 2026-10-14 17:09 | B2: 4055ede | C2: 1. Reference avant sol texture | D2: defaut (qualite adaptative), en mouvement | E2: 1 | F2: defaut / public | G2: 7.23 | H2: =IF(G2>0,1000/G2,"") | I2: 5.95 | J2: 5.58 | K2: 1.364 | L2: 1.874 | O2: reference_avant_sol
A3: 2026-10-14 17:09 | B3: 4055ede | C3: 1. Reference avant sol texture | D3: defaut (qualite adaptative), en mouvement | E3: 1 | F3: defaut / scene | G3: 7.35 | H3: =IF(G3>0,1000/G3,"") | I3: 5.99 | J3: 5.62 | K3: 1.303 | L3: 1.873 | O3: reference_avant_sol
A4: 2026-10-14 17:09 | B4: 4055ede | C4: 1. Reference avant sol texture | D4: defaut (qualite adaptative), en mouvement | E4: 1 | F4: defaut / sous les trusses | G4: 6.78 | H4: =IF(G4>0,1000/G4,"") | I4: 5.59 | J4: 5.22 | K4: 1.061 | L4: 1.612 | O4: reference_avant_sol
A5: 2026-10-14 17:09 | B5: 4055ede | C5: 1. Reference avant sol texture | D5: defaut (qualite adaptative), en mouvement | E5: 1 | F5: gobo + prisme 8 + zoom 25 / public | G5: 14.74 | H5: =IF(G5>0,1000/G5,"") | I5: 14.13 | J5: 14.03 | K5: 5.174 | L5: 4.95 | O5: reference_avant_sol
A6: 2026-10-14 17:09 | B6: 4055ede | C6: 1. Reference avant sol texture | D6: defaut (qualite adaptative), en mouvement | E6: 1 | F6: gobo + prisme 8 + zoom 25 / scene | G6: 13.82 | H6: =IF(G6>0,1000/G6,"") | I6: 13.23 | J6: 13.25 | K6: 4.312 | L6: 4.858 | O6: reference_avant_sol
A7: 2026-10-14 17:09 | B7: 4055ede | C7: 1. Reference avant sol texture | D7: defaut (qualite adaptative), en mouvement | E7: 1 | F7: gobo + prisme 8 + zoom 25 / sous les trusses | G7: 10.59 | H7: =IF(G7>0,1000/G7,"") | I7: 10.1 | J7: 9.85 | K7: 2.875 | L7: 2.879 | O7: reference_avant_sol
A8: 2026-10-14 17:09 | B8: 4055ede | C8: 1. Reference avant sol texture | D8: defaut (qualite adaptative), en mouvement | E8: 1 | F8: zoom 45 + frost 0.6 / public | G8: 10.33 | H8: =IF(G8>0,1000/G8,"") | I8: 7.44 | J8: 7.36 | K8: 1.989 | L8: 3.203 | O8: reference_avant_sol
A9: 2026-10-14 17:09 | B9: 4055ede | C9: 1. Reference avant sol texture | D9: defaut (qualite adaptative), en mouvement | E9: 1 | F9: zoom 45 + frost 0.6 / scene | G9: 10.35 | H9: =IF(G9>0,1000/G9,"") | I9: 7.7 | J9: 7.6 | K9: 2.238 | L9: 3.197 | O9: reference_avant_sol
A10: 2026-10-14 17:09 | B10: 4055ede | C10: 1. Reference avant sol texture | D10: defaut (qualite adaptative), en mouvement | E10: 1 | F10: zoom 45 + frost 0.6 / sous les trusses | G10: 8.64 | H10: =IF(G10>0,1000/G10,"") | I10: 7.22 | J10: 6.57 | K10: 1.334 | L10: 2.925 | O10: reference_avant_sol
A11: 2026-10-14 17:09 | B11: 4055ede | C11: 1. Reference avant sol texture | D11: defaut (qualite adaptative), en mouvement | E11: 1 | F11: sans rebonds (GI) | G11: 6.61 | H11: =IF(G11>0,1000/G11,"") | I11: 5.24 | J11: 5.04 | K11: 1.147 | L11: 1.426 | O11: reference_avant_sol
A12: 2026-10-14 17:09 | B12: 4055ede | C12: 1. Reference avant sol texture | D12: defaut (qualite adaptative), en mouvement | E12: 1 | F12: sans fumee volumetrique | G12: 5.16 | H12: =IF(G12>0,1000/G12,"") | I12: 2.76 | J12: 2.64 | K12: 1.407 | L12: 0 | O12: reference_avant_sol
A13: 2026-10-14 17:09 | B13: 4055ede | C13: 1. Reference avant sol texture | D13: defaut (qualite adaptative), en mouvement | E13: 1 | F13: sans taches sur surfaces | G13: 6.31 | H13: =IF(G13>0,1000/G13,"") | I13: 5.21 | J13: 4.89 | K13: 0.609 | L13: 1.977 | O13: reference_avant_sol
... A43: 2026-10-14 19:08 | B43: eec6ca5 | C43: 3. Sol mouille 0,8 + reflet miroir | D43: adaptive=0, en mouvement | E43: 2 | F43: sans bloom | G43: 8.015 | H43: =IF(G43>0,1000/G43,"") | I43: 6.695 | J43: 6.215 | K43: 1.626 | L43: 1.931 | O43: mouille4_A, mouille4_B
A44: 2026-10-14 19:08 | B44: eec6ca5 | C44: 3. Sol mouille 0,8 + reflet miroir | D44: adaptive=0, en mouvement | E44: 2 | F44: sol mouille / public | G44: 10.435 | H44: =IF(G44>0,1000/G44,"") | I44: 8.595 | J44: 8.185 | K44: 1.661 | L44: 1.907 | M44: 0.971 | O44: mouille4_A, mouille4_B
A45: 2026-10-14 19:08 | B45: eec6ca5 | C45: 3. Sol mouille 0,8 + reflet miroir | D45: adaptive=0, en mouvement | E45: 2 | F45: sol mouille + gobo + prisme 8 / scene | G45: 20.855 | H45: =IF(G45>0,1000/G45,"") | I45: 20.31 | J45: 20.185 | K45: 5.138 | L45: 6.096 | M45: 3.641 | O45: mouille4_A, mouille4_B
A46: 2026-10-14 19:14 | B46: eec6ca5 +modifs | C46: 4. Faisceaux coupes aux obstacles + cube (banc rapide) | D46: adaptive=0, en mouvement, 3 cas | E46: 2 | F46: defaut / public | G46: 8.495 | H46: =IF(G46>0,1000/G46,"") | I46: 7.205 | J46: 6.97 | K46: 1.584 | L46: 1.866 | O46: obstacles_B0, obstacles_B1
A47: 2026-10-14 19:14 | B47: eec6ca5 +modifs | C47: 4. Faisceaux coupes aux obstacles + cube (banc rapide) | D47: adaptive=0, en mouvement, 3 cas | E47: 2 | F47: gobo + prisme 8 + zoom 25 / public | G47: 19.92 | H47: =IF(G47>0,1000/G47,"") | I47: 18.64 | J47: 18.59 | K47: 6.374 | L47: 6.175 | O47: obstacles_B0, obstacles_B1
A48: 2026-10-14 19:14 | B48: eec6ca5 +modifs | C48: 4. Faisceaux coupes aux obstacles + cube (banc rapide) | D48: adaptive=0, en mouvement, 3 cas | E48: 2 | F48: zoom 45 + frost 0.6 / public | G48: 10.435 | H48: =IF(G48>0,1000/G48,"") | I48: 8.925 | J48: 8.145 | K48: 2.242 | L48: 3.275 | O48: obstacles_B0, obstacles_B1
A49: 2026-10-14 19:59 | B49: eec6ca5 +modifs | C49: 5a. Ombres coupees (shadows=0) | D49: adaptive=0, en mouvement, shadows=0 | E49: 2 | F49: defaut / public | G49: 8.74 | H49: =IF(G49>0,1000/G49,"") | I49: 7.115 | J49: 6.615 | K49: 1.638 | L49: 1.977 | N49: 0 | O49: ombres_final2_A0, ombres_final2_A1
A50: 2026-10-14 19:59 | B50: eec6ca5 +modifs | C50: 5a. Ombres coupees (shadows=0) | D50: adaptive=0, en mouvement, shadows=0 | E50: 2 | F50: defaut / scene | G50: 8.675 | H50: =IF(G50>0,1000/G50,"") | I50: 7.06 | J50: 6.65 | K50: 1.623 | L50: 1.975 | N50: 0 | O50: ombres_final2_A0, ombres_final2_A1
A51: 2026-10-14 19:59 | B51: eec6ca5 +modifs | C51: 5a. Ombres coupees (shadows=0) | D51: adaptive=0, en mouvement, shadows=0 | E51: 2 | F51: defaut / sous les trusses | G51: 7.88 | H51: =IF(G51>0,1000/G51,"") | I51: 6.395 | J51: 5.915 | K51: 1.137 | L51: 1.672 | N51: 0 | O51: ombres_final2_A0, ombres_final2_A1
A52: 2026-10-14 19:59 | B52: eec6ca5 +modifs | C52: 5a. Ombres coupees (shadows=0) | D52: adaptive=0, en mouvement, shadows=0 | E52: 2 | F52: gobo + prisme 8 + zoom 25 / public | G52: 19.44 | H52: =IF(G52>0,1000/G52,"") | I52: 17.615 | J52: 17.23 | K52: 6.065 | L52: 6.614 | N52: 0 | O52: ombres_final2_A0, ombres_final2_A1
A53: 2026-10-14 19:59 | B53: eec6ca5 +modifs | C53: 5a. Ombres coupees (shadows=0) | D53: adaptive=0, en mouvement, shadows=0 | E53: 2 | F53: gobo + prisme 8 + zoom 25 / scene | G53: 18.355 | H53: =IF(G53>0,1000/G53,"") | I53: 16.575 | J53: 16.325 | K53: 5.197 | L53: 6.37 | N53: 0 | O53: ombres_final2_A0, ombres_final2_A1
A54: 2026-10-14 19:59 | B54: eec6ca5 +modifs | C54: 5a. Ombres coupees (shadows=0) | D54: adaptive=0, en mouvement, shadows=0 | E54: 2 | F54: gobo + prisme 8 + zoom 25 / sous les trusses | G54: 13.445 | H54: =IF(G54>0,1000/G54,"") | I54: 11.915 | J54: 11.755 | K54: 3.175 | L54: 3.757 | N54: 0 | O54: ombres_final2_A0, ombres_final2_A1
A55: 2026-10-14 19:59 | B55: eec6ca5 +modifs | C55: 5a. Ombres coupees (shadows=0) | D55: adaptive=0, en mouvement, shadows=0 | E55: 2 | F55: zoom 45 + frost 0.6 / public | G55: 11.995 | H55: =IF(G55>0,1000/G55,"") | I55: 10.445 | J55: 8.9 | K55: 2.351 | L55: 3.543 | N55: 0 | O55: ombres_final2_A0, ombres_final2_A1
A56: 2026-10-14 19:59 | B56: eec6ca5 +modifs | C56: 5a. Ombres coupees (shadows=0) | D56: adaptive=0, en mouvement, shadows=0 | E56: 2 | F56: zoom 45 + frost 0.6 / scene | G56: 12.17 | H56: =IF(G56>0,1000/G56,"") | I56: 10.63 | J56: 9.515 | K56: 2.628 | L56: 3.561 | N56: 0 | O56: ombres_final2_A0, ombres_final2_A1
A57: 2026-10-14 19:59 | B57: eec6ca5 +modifs | C57: 5a. Ombres coupees (shadows=0) | D57: adaptive=0, en mouvement, shadows=0 | E57: 2 | F57: zoom 45 + frost 0.6 / sous les trusses | G57: 9.825 | H57: =IF(G57>0,1000/G57,"") | I57: 8.03 | J57: 7.455 | K57: 1.451 | L57: 3.204 | N57: 0 | O57: ombres_final2_A0, ombres_final2_A1
A58: 2026-10-14 19:59 | B58: eec6ca5 +modifs | C58: 5a. Ombres coupees (shadows=0) | D58: adaptive=0, en mouvement, shadows=0 | E58: 2 | F58: sans rebonds (GI) | G58: 7.915 | H58: =IF(G58>0,1000/G58,"") | I58: 6.39 | J58: 5.845 | K58: 1.38 | L58: 1.509 | N58: 0 | O58: ombres_final2_A0, ombres_final2_A1
A59: 2026-10-14 19:59 | B59: eec6ca5 +modifs | C59: 5a. Ombres coupees (shadows=0) | D59: adaptive=0, en mouvement, shadows=0 | E59: 2 | F59: sans fumee volumetrique | G59: 5.54 | H59: =IF(G59>0,1000/G59,"") | I59: 4.335 | J59: 3.985 | K59: 1.638 | L59: 0 | N59: 0 | O59: ombres_final2_A0, ombres_final2_A1
A60: 2026-10-14 19:59 | B60: eec6ca5 +modifs | C60: 5a. Ombres coupees (shadows=0) | D60: adaptive=0, en mouvement, shadows=0 | E60: 2 | F60: sans taches sur surfaces | G60: 7.9 | H60: =IF(G60>0,1000/G60,"") | I60: 6.31 | J60: 5.675 | K60: 0.748 | L60: 2.065 | N60: 0 | O60: ombres_final2_A0, ombres_final2_A1
... A62: 2026-10-14 19:59 | B62: eec6ca5 +modifs | C62: 5a. Ombres coupees (shadows=0) | D62: adaptive=0, en mouvement, shadows=0 | E62: 2 | F62: sans bloom | G62: 8.68 | H62: =IF(G62>0,1000/G62,"") | I62: 6.715 | J62: 6.32 | K62: 1.687 | L62: 2.034 | N62: 0 | O62: ombres_final2_A0, ombres_final2_A1
A63: 2026-10-14 19:59 | B63: eec6ca5 +modifs | C63: 5a. Ombres coupees (shadows=0) | D63: adaptive=0, en mouvement, shadows=0 | E63: 2 | F63: sol mouille / public | G63: 10.365 | H63: =IF(G63>0,1000/G63,"") | I63: 9.085 | J63: 8.365 | K63: 1.747 | L63: 2.048 | M63: 1.031 | N63: 0 | O63: ombres_final2_A0, ombres_final2_A1
A64: 2026-10-14 19:59 | B64: eec6ca5 +modifs | C64: 5a. Ombres coupees (shadows=0) | D64: adaptive=0, en mouvement, shadows=0 | E64: 2 | F64: sol mouille + gobo + prisme 8 / scene | G64: 23.035 | H64: =IF(G64>0,1000/G64,"") | I64: 21.165 | J64: 20.745 | K64: 5.532 | L64: 6.531 | M64: 3.545 | N64: 0 | O64: ombres_final2_A0, ombres_final2_A1
A65: 2026-10-14 19:59 | B65: eec6ca5 +modifs | C65: 5b. Ombres des obstacles (shadows=1) | D65: adaptive=0, en mouvement, shadows=1 | E65: 2 | F65: defaut / public | G65: 9.105 | H65: =IF(G65>0,1000/G65,"") | I65: 7.3 | J65: 6.87 | K65: 1.748 | L65: 2.116 | N65: 95 | O65: ombres_final2_B0, ombres_final2_B1
A66: 2026-10-14 19:59 | B66: eec6ca5 +modifs | C66: 5b. Ombres des obstacles (shadows=1) | D66: adaptive=0, en mouvement, shadows=1 | E66: 2 | F66: defaut / scene | G66: 8.96 | H66: =IF(G66>0,1000/G66,"") | I66: 7.22 | J66: 6.855 | K66: 1.701 | L66: 2.041 | N66: 95 | O66: ombres_final2_B0, ombres_final2_B1
A67: 2026-10-14 19:59 | B67: eec6ca5 +modifs | C67: 5b. Ombres des obstacles (shadows=1) | D67: adaptive=0, en mouvement, shadows=1 | E67: 2 | F67: defaut / sous les trusses | G67: 8.16 | H67: =IF(G67>0,1000/G67,"") | I67: 6.66 | J67: 6.195 | K67: 1.192 | L67: 1.791 | N67: 95 | O67: ombres_final2_B0, ombres_final2_B1
A68: 2026-10-14 19:59 | B68: eec6ca5 +modifs | C68: 5b. Ombres des obstacles (shadows=1) | D68: adaptive=0, en mouvement, shadows=1 | E68: 2 | F68: gobo + prisme 8 + zoom 25 / public | G68: 20.915 | H68: =IF(G68>0,1000/G68,"") | I68: 18.99 | J68: 18.735 | K68: 6.575 | L68: 7.388 | N68: 282 | O68: ombres_final2_B0, ombres_final2_B1
A69: 2026-10-14 19:59 | B69: eec6ca5 +modifs | C69: 5b. Ombres des obstacles (shadows=1) | D69: adaptive=0, en mouvement, shadows=1 | E69: 2 | F69: gobo + prisme 8 + zoom 25 / scene | G69: 19.46 | H69: =IF(G69>0,1000/G69,"") | I69: 17.455 | J69: 17.21 | K69: 5.513 | L69: 6.965 | N69: 282 | O69: ombres_final2_B0, ombres_final2_B1
A70: 2026-10-14 19:59 | B70: eec6ca5 +modifs | C70: 5b. Ombres des obstacles (shadows=1) | D70: adaptive=0, en mouvement, shadows=1 | E70: 2 | F70: gobo + prisme 8 + zoom 25 / sous les trusses | G70: 14.375 | H70: =IF(G70>0,1000/G70,"") | I70: 12.79 | J70: 12.46 | K70: 3.581 | L70: 4.171 | N70: 282 | O70: ombres_final2_B0, ombres_final2_B1
...

Sheet Comparaison
A1: img/s reelles
A2: Cas | B2: 1. Reference avant sol texture | C2: 2. Sol beton texture (Concrete031) | D2: 3. Sol mouille 0,8 + reflet miroir | E2: 4. Faisceaux coupes aux obstacles + cube (banc rapide) | F2: 5a. Ombres coupees (shadows=0) | G2: 5b. Ombres des obstacles (shadows=1) | H2: 6a. Ombres + penombre : coupees (shadows=0) | I2: 6b. Ombres + penombre sur surfaces (shadows=1) | J2: 7a. Aberration chromatique codee, coupee (atlas R32F garde) | K2: 7b. Aberration chromatique coupee (banc rapide) | L2: 7c. Aberration chromatique active (banc rapide) | M2: 7e0. Essai v0 : aberration, enveloppe +2 %, chroma=1 | N2: 7e1. Essai v1 : enveloppe inchangee, flou par couleur, chroma=1 | O2: 7e3. Essai v3 : cache pour toutes les lyres, chroma=1 | P2: 7e4. Essai v4 : cache recalcule s'il change (RGBA16F), chroma=1 | Q2: 8. Longueur exacte des faisceaux arretes par le sol (bout des taches rasantes) | R2: 9a. Eau au sol : creux, flaques nettes, variante seche du shader | S2: 9b. Eau au sol a 10 % | T2: 9e. Essai : creux en trilineaire (abandonne) | U2: 10a. Reflet seulement dans l'eau (masque par blocs), eau 0,1 | V2: 10b. Reflet seulement dans l'eau, eau 0,3 | W2: 10c. Reflet seulement dans l'eau, eau 1 | X2: 10e1. Essai masque : 1 point par pixel du miroir (creux manques) | Y2: 10e3. Essai masque : faisceaux seulement dans les flaques (pores plus sombres) | Z2: 11. Lasers (prototype) : banc des lyres inchange | AA2: 11a. Lasers : triangles en addition (prototype) | AB2: 11b. Lasers : tuiles en calcul (prototype) | AC2: 12. Lasers : traits seuls (eventails de 16 traits au plus), nappe lisse allegee, triangles retires | AD2: 13a. Lasers, essai degrades v1 (meme shader, 6 vec4) | AE2: 13b. Lasers, essai degrades v2 (interpolation allegee) | AF2: 13c. Lasers, degrades : deux variantes du shader (gardee) | AG2: 13. Lasers : moteur et onglet Lasers (etape 2), formes, degrades, effets, boitiers, cas L7 | AH2: 14. Lasers : fumee de la piece (coupee, laserfog=0) | AI2: 14. Lasers : fumee de la piece (laserfog=1) | AJ2: 15. Lasers : diffusion avant 1 lobe (laserphase=0) | AK2: 15. Lasers : diffusion avant 2 lobes (laserphase=1) | AL2: 16. Lasers : volutes coupees (volutes=0) | AM2: 16. Lasers : volutes 1 octave (BC5 64^3, 1,6 m) | AN2: 17. Lasers : volutes, 2e octave coupee (volfine=0) | AO2: 17. Lasers : volutes, 2e octave de pres (volfine=1, portee -1) | AP2: 18. Lasers : variantes du shader, tout coupe (variante 0) | AQ2: 18. Lasers : variante 1 (fumee de la piece, 2 lobes) | AR2: 18. Lasers : variante 3 (+ volutes, 2 octaves) | AS2: 19. Lasers : etape 3 avant (reference) | AT2: 19. Lasers : etape 3 finale (fumee de la piece RG8, 2 lobes, volutes) | AU2: 19. Lyres : etape 3 finale (texture des amas RG8) | AV2: 20. Lasers : lecture ILDA, mode ligne, 16 384 segments | AW2: 20a. Essai ecarte : variante nappes et traits seuls (coupee) | AX2: 20a. Essai ecarte : variante nappes et traits seuls (active) | AY2: 20. Lyres : lecture ILDA (inchange) | AZ2: 21. Lasers : collisions, code present coupe (lasercoll=0) | BA2: 21. Lasers : collisions actives (essai, test avec branchement) | BB2: 22. Lasers : impacts coupes (laserimpacts=0) | BC2: 22. Lasers : impacts sur les surfaces | BD2: 22b. Lasers : etape 5 (collisions + impacts), en mouvement | BE2: 22b. Lyres : etape 5 (inchange) | BF2: 23. arcs : silhouettes adoucies, pyramide coupee a l'ecran et aux parois, passe des arcs a part | BG2: 24. Lasers : etape 9 (moteur de trace, arcs arretes sur les faces, formes par trace, plusieurs coeurs, cache des figures fixes) | BH2: 24. Lyres : etape 9 (inchange) | BI2: 25. Lasers : sorties sans traits parasites, blanchiment (camera) et lueur de sortie | BJ2: 25. Lyres : sorties et blanchiment des lasers (inchange) | BK2: 26. Lyres superposees a 1/4 (cases chargees) + diffus par direction des lyres douces + gobo ouvert sans lecture | BL2: 27. Lyres superposees a 1/4 seulement pour les grandes taches floues + scintillement du sol + variante legere des lyres frost | BM2: 28. AMD FSR 1 (EASU + RCAS), coupe par defaut | BN2: 29. Faisceaux 1/2 et 1/4 : flou a la taille d'un pixel de la fumee (plus de marches au bord des cones) | BO2: 30. Lasers : rendu photo (bords brillants 1, halo 0,1) + corrections des coupes | BP2: 30. Lasers : rendu photo, bords et halo coupes (laseredge=0, laserhalo=0) | BQ2: 30. Lyres : rendu photo des lasers (inchange) | BR2: 31. Lasers : convergence RGB 0,3 mrad + aberration objectif 0,2 % (avec le rendu photo) | BS2: 31. Lasers : convergence et objectif coupes (laserconv=0, laserlensca=0) | BT2: 31. Lyres : convergence RGB des lasers (inchange) | BU2: 32. Lasers : convergence RGB, un seul calcul pour les couleurs pures | BV2: 32. Lasers : L7 multicolore, rendu photo et convergence actifs | BW2: 32. Lasers : L7 multicolore, convergence et objectif coupes | BX2: 33. Fumee des lasers v2, etape 1 : texture des amas en RGBA8 (modele Classique) | BY2: 33. Fumee des lasers v2, etape 1 : modele Spatiale (carte seule, variante 1) | BZ2: 34. Fumee des lasers v2, etape 2 : nuages par erosion (variante 4) | CA2: 34. Fumee des lasers v2, etape 2 : sans les nuages (sferode=0, variante 1) | CB2: 34. Fumee des lasers v2, etape 2 : modele Classique (meme executable) | CC2: 34. Fumee des lasers v2, etape 2 : banc des lyres | CD2: 35. Fumee des lasers v2, etape 3 : tourbillons (3 sinus), sans filaments (variante 4) [INVALIDE : variante 2 du Classique mesuree (erreur corrigee), voir 37] | CE2: 35. Fumee des lasers v2, etape 3 : tourbillons et filaments de pres (variante 5 si un eventail passe pres) | CF2: 35. Fumee des lasers v2, etape 3 : modele Classique (bloc d'uniformes agrandi) | CG2: 36. Fumee des lasers v2, etape 4 : Classique (meme executable) | CH2: 36. Fumee des lasers v2, etape 4 : prereglage 3 Concert | CI2: 36. Fumee des lasers v2, etape 4 : prereglage 1 Hazer propre | CJ2: 36. Fumee des lasers v2, etape 4 : prereglage 5 Marbre de pres | CK2: 37. Fumee des lasers v2 : bancs seuilles par pixel, bords nuageux ; Classique (meme executable) | CL2: 37. Fumee des lasers v2 : bancs seuilles par pixel, bords nuageux ; Concert sans filaments (variante 4) | CM2: 37. Fumee des lasers v2 : bancs seuilles par pixel, bords nuageux ; Concert avec filaments (variante 5) | CN2: 38. Fumee des lasers v2 : salle composee ; Classique (meme executable) | CO2: 38. Fumee des lasers v2 : salle composee (sfpreset=6, filaments de l'utilisateur : force 1, 2 m, portee 1) | CP2: 38. Fumee des lasers v2 : salle composee sans filaments | CQ2: 39. Fumee des lasers v2 : salle composee en degrade (deux ambiances superposees) ; Classique (meme executable) | CR2: 39. Fumee des lasers v2 : salle composee en degrade (sfpreset=6, filaments de l'utilisateur) | CS2: 39. Fumee des lasers v2 : salle composee en degrade, sans filaments | CT2: 40. Spectacles laser (generateur de 30 scenes, 10 effets ajoutes) : banc des lasers inchange (avant -3,1 a +1,6 %, images identiques) | CU2: 41. Lasers : convergence RGB optimisee (traits en un calcul, impacts plafonnes, variante sans convergence, halo au quart, franges invisibles sautees, impacts des arcs) | CV2: 41. Lasers : convergence et objectif coupes (meme executable) | CW2: 42. Lasers : impacts en quadrilatere exact (au lieu de carres de marge) + bords des nappes par couleur seulement pres du bord | CX2: 43. Optim. lasers etape 1 : journal par image (fumee CPU, Present) et compteurs de mesure (--stats) ; image et shaders inchanges | CY2: 44. Optim. lasers etape 2 : fumee CPU en tache de fond (3 coeurs) ; presentation avec dechirure (bancs : 2 tampons, spectacle : 3 tampons, latence 2) | CZ2: 45. Optim. lasers etape 3 : passes de fumee des lyres sautees sans lyre allumee (0.9) ; 0.3 et 0.4 essayes, sans gain, retires | DA2: 46. Optim. lasers etape 4 (essai, non garde) : lumiere lente interpolee par tuile sur les nappes planes, tolerance 2 % | DB2: 47. Optim. lasers etape 5 : morceaux voisins d'un meme cercle fusionnes (cones : 2 morceaux par cercle au lieu de 4) | DC2: 48. Optim. lasers etape 7 : resolution adaptative des lasers (80, 70, 50 % sous 60 img/s), agrandissement selon la profondeur | DD2: 49. Impacts des arcs : decoupage par face en tranches de 22,5 deg (traits au sol qui clignotaient) | DE2: 50. Impacts : largeur minimale comptee a l'ecran (traits au sol en pointilles au loin), laserhitmin=0 | DF2: 50. Impacts : largeur minimale comptee a l'ecran (traits au sol en pointilles au loin), laserhitmin=1 | DG2: 51. Lumiere des lasers dans la piece (VPL dans les sondes), lasergi=0 | DH2: 51. Lumiere des lasers dans la piece (VPL dans les sondes), lasergi=1 | DI2: 51. Lumiere des lasers dans la piece : banc des lyres (lasergi=0 par defaut) | DJ2: 52. Reflets du sol mouille : lasers dans le reflet, beton mouille flou, flou des flaques | DK2: 52. Reflets du sol mouille : banc des lasers
A3: defaut / public | B3: =IFERROR(AVERAGEIFS(Mesures!$H:$H,Mesures!$F:$F,$A3,Mesures!$C:$C,B$2),"") | C3: =IFERROR(AVERAGEIFS(Mesures!$H:$H,Mesures!$F:$F,$A3,Mesures!$C:$C,C$2),"") | D3: =IFERROR(AVERAGEIFS(Mesures!$H:$H,Mesures!$F:$F,$A3,Mesures!$C:$C,D$2),"") | E3: =IFERROR(AVERAGEIFS(Mesures!$H:$H,Mesures!$F:$F,$A3,Mesures!$C:$C,E$2),"") | F3: =IFERROR(AVERAGEIFS(Mesures!$H:$H,Mesures!$F:$F,$A3,Mesures!$C:$C,F$2),"") | G3: =IFERROR(AVERAGEIFS(Mesures!$H:$H,Mesures!$F:$F,$A3,Mesures!$C:$C,G$2),"") | H3: =IFERROR(AVERAGEIFS(Mesures!$H:$H,Mesures!$F:$F,$A3,Mesures!$C:$C,H$2),"") | I3: =IFERROR(AVERAGEIFS(Mesures!$H:$H,Mesures!$F:$F,$A3,Mesures!$C:$C,I$2),"") | ... DK3: =IFERROR(AVERAGEIFS(Mesures!$H:$H,Mesures!$F:$F,$A3,Mesures!$C:$C,DK$2),"")
A4: defaut / scene | B4: =IFERROR(AVERAGEIFS(Mesures!$H:$H,Mesures!$F:$F,$A4,Mesures!$C:$C,B$2),"") | C4: =IFERROR(AVERAGEIFS(Mesures!$H:$H,Mesures!$F:$F,$A4,Mesures!$C:$C,C$2),"") | D4: =IFERROR(AVERAGEIFS(Mesures!$H:$H,Mesures!$F:$F,$A4,Mesures!$C:$C,D$2),"") | E4: =IFERROR(AVERAGEIFS(Mesures!$H:$H,Mesures!$F:$F,$A4,Mesures!$C:$C,E$2),"") | F4: =IFERROR(AVERAGEIFS(Mesures!$H:$H,Mesures!$F:$F,$A4,Mesures!$C:$C,F$2),"") | G4: =IFERROR(AVERAGEIFS(Mesures!$H:$H,Mesures!$F:$F,$A4,Mesures!$C:$C,G$2),"") | H4: =IFERROR(AVERAGEIFS(Mesures!$H:$H,Mesures!$F:$F,$A4,Mesures!$C:$C,H$2),"") | I4: =IFERROR(AVERAGEIFS(Mesures!$H:$H,Mesures!$F:$F,$A4,Mesures!$C:$C,I$2),"") | ... DK4: =IFERROR(AVERAGEIFS(Mesures!$H:$H,Mesures!$F:$F,$A4,Mesures!$C:$C,DK$2),"")
A5: defaut / sous les trusses | B5: =IFERROR(AVERAGEIFS(Mesures!$H:$H,Mesures!$F:$F,$A5,Mesures!$C:$C,B$2),"") | C5: =IFERROR(AVERAGEIFS(Mesures!$H:$H,Mesures!$F:$F,$A5,Mesures!$C:$C,C$2),"") | D5: =IFERROR(AVERAGEIFS(Mesures!$H:$H,Mesures!$F:$F,$A5,Mesures!$C:$C,D$2),"") | E5: =IFERROR(AVERAGEIFS(Mesures!$H:$H,Mesures!$F:$F,$A5,Mesures!$C:$C,E$2),"") | F5: =IFERROR(AVERAGEIFS(Mesures!$H:$H,Mesures!$F:$F,$A5,Mesures!$C:$C,F$2),"") | G5: =IFERROR(AVERAGEIFS(Mesures!$H:$H,Mesures!$F:$F,$A5,Mesures!$C:$C,G$2),"") | H5: =IFERROR(AVERAGEIFS(Mesures!$H:$H,Mesures!$F:$F,$A5,Mesures!$C:$C,H$2),"") | I5: =IFERROR(AVERAGEIFS(Mesures!$H:$H,Mesures!$F:$F,$A5,Mesures!$C:$C,I$2),"") | ... DK5: =IFERROR(AVERAGEIFS(Mesures!$H:$H,Mesures!$F:$F,$A5,Mesures!$C:$C,DK$2),"")
A6: gobo + prisme 8 + zoom 25 / public | B6: =IFERROR(AVERAGEIFS(Mesures!$H:$H,Mesures!$F:$F,$A6,Mesures!$C:$C,B$2),"") | C6: =IFERROR(AVERAGEIFS(Mesures!$H:$H,Mesures!$F:$F,$A6,Mesures!$C:$C,C$2),"") | D6: =IFERROR(AVERAGEIFS(Mesures!$H:$H,Mesures!$F:$F,$A6,Mesures!$C:$C,D$2),"") | E6: =IFERROR(AVERAGEIFS(Mesures!$H:$H,Mesures!$F:$F,$A6,Mesures!$C:$C,E$2),"") | F6: =IFERROR(AVERAGEIFS(Mesures!$H:$H,Mesures!$F:$F,$A6,Mesures!$C:$C,F$2),"") | G6: =IFERROR(AVERAGEIFS(Mesures!$H:$H,Mesures!$F:$F,$A6,Mesures!$C:$C,G$2),"") | H6: =IFERROR(AVERAGEIFS(Mesures!$H:$H,Mesures!$F:$F,$A6,Mesures!$C:$C,H$2),"") | I6: =IFERROR(AVERAGEIFS(Mesures!$H:$H,Mesures!$F:$F,$A6,Mesures!$C:$C,I$2),"") | ... DK6: =IFERROR(AVERAGEIFS(Mesures!$H:$H,Mesures!$F:$F,$A6,Mesures!$C:$C,DK$2),"")
A7: gobo + prisme 8 + zoom 25 / scene | B7: =IFERROR(AVERAGEIFS(Mesures!$H:$H,Mesures!$F:$F,$A7,Mesures!$C:$C,B$2),"") | C7: =IFERROR(AVERAGEIFS(Mesures!$H:$H,Mesures!$F:$F,$A7,Mesures!$C:$C,C$2),"") | D7: =IFERROR(AVERAGEIFS(Mesures!$H:$H,Mesures!$F:$F,$A7,Mesures!$C:$C,D$2),"") | E7: =IFERROR(AVERAGEIFS(Mesures!$H:$H,Mesures!$F:$F,$A7,Mesures!$C:$C,E$2),"") | F7: =IFERROR(AVERAGEIFS(Mesures!$H:$H,Mesures!$F:$F,$A7,Mesures!$C:$C,F$2),"") | G7: =IFERROR(AVERAGEIFS(Mesures!$H:$H,Mesures!$F:$F,$A7,Mesures!$C:$C,G$2),"") | H7: =IFERROR(AVERAGEIFS(Mesures!$H:$H,Mesures!$F:$F,$A7,Mesures!$C:$C,H$2),"") | I7: =IFERROR(AVERAGEIFS(Mesures!$H:$H,Mesures!$F:$F,$A7,Mesures!$C:$C,I$2),"") | ... DK7: =IFERROR(AVERAGEIFS(Mesures!$H:$H,Mesures!$F:$F,$A7,Mesures!$C:$C,DK$2),"")
A8: gobo + prisme 8 + zoom 25 / sous les trusses | B8: =IFERROR(AVERAGEIFS(Mesures!$H:$H,Mesures!$F:$F,$A8,Mesures!$C:$C,B$2),"") | C8: =IFERROR(AVERAGEIFS(Mesures!$H:$H,Mesures!$F:$F,$A8,Mesures!$C:$C,C$2),"") | D8: =IFERROR(AVERAGEIFS(Mesures!$H:$H,Mesures!$F:$F,$A8,Mesures!$C:$C,D$2),"") | E8: =IFERROR(AVERAGEIFS(Mesures!$H:$H,Mesures!$F:$F,$A8,Mesures!$C:$C,E$2),"") | F8: =IFERROR(AVERAGEIFS(Mesures!$H:$H,Mesures!$F:$F,$A8,Mesures!$C:$C,F$2),"") | G8: =IFERROR(AVERAGEIFS(Mesures!$H:$H,Mesures!$F:$F,$A8,Mesures!$C:$C,G$2),"") | H8: =IFERROR(AVERAGEIFS(Mesures!$H:$H,Mesures!$F:$F,$A8,Mesures!$C:$C,H$2),"") | I8: =IFERROR(AVERAGEIFS(Mesures!$H:$H,Mesures!$F:$F,$A8,Mesures!$C:$C,I$2),"") | ... DK8: =IFERROR(AVERAGEIFS(Mesures!$H:$H,Mesures!$F:$F,$A8,Mesures!$C:$C,DK$2),"")
A9: zoom 45 + frost 0.6 / public | B9: =IFERROR(AVERAGEIFS(Mesures!$H:$H,Mesures!$F:$F,$A9,Mesures!$C:$C,B$2),"") | C9: =IFERROR(AVERAGEIFS(Mesures!$H:$H,Mesures!$F:$F,$A9,Mesures!$C:$C,C$2),"") | D9: =IFERROR(AVERAGEIFS(Mesures!$H:$H,Mesures!$F:$F,$A9,Mesures!$C:$C,D$2),"") | E9: =IFERROR(AVERAGEIFS(Mesures!$H:$H,Mesures!$F:$F,$A9,Mesures!$C:$C,E$2),"") | F9: =IFERROR(AVERAGEIFS(Mesures!$H:$H,Mesures!$F:$F,$A9,Mesures!$C:$C,F$2),"") | G9: =IFERROR(AVERAGEIFS(Mesures!$H:$H,Mesures!$F:$F,$A9,Mesures!$C:$C,G$2),"") | H9: =IFERROR(AVERAGEIFS(Mesures!$H:$H,Mesures!$F:$F,$A9,Mesures!$C:$C,H$2),"") | I9: =IFERROR(AVERAGEIFS(Mesures!$H:$H,Mesures!$F:$F,$A9,Mesures!$C:$C,I$2),"") | ... DK9: =IFERROR(AVERAGEIFS(Mesures!$H:$H,Mesures!$F:$F,$A9,Mesures!$C:$C,DK$2),"")
A10: zoom 45 + frost 0.6 / scene | B10: =IFERROR(AVERAGEIFS(Mesures!$H:$H,Mesures!$F:$F,$A10,Mesures!$C:$C,B$2),"") | C10: =IFERROR(AVERAGEIFS(Mesures!$H:$H,Mesures!$F:$F,$A10,Mesures!$C:$C,C$2),"") | D10: =IFERROR(AVERAGEIFS(Mesures!$H:$H,Mesures!$F:$F,$A10,Mesures!$C:$C,D$2),"") | E10: =IFERROR(AVERAGEIFS(Mesures!$H:$H,Mesures!$F:$F,$A10,Mesures!$C:$C,E$2),"") | F10: =IFERROR(AVERAGEIFS(Mesures!$H:$H,Mesures!$F:$F,$A10,Mesures!$C:$C,F$2),"") | G10: =IFERROR(AVERAGEIFS(Mesures!$H:$H,Mesures!$F:$F,$A10,Mesures!$C:$C,G$2),"") | H10: =IFERROR(AVERAGEIFS(Mesures!$H:$H,Mesures!$F:$F,$A10,Mesures!$C:$C,H$2),"") | I10: =IFERROR(AVERAGEIFS(Mesures!$H:$H,Mesures!$F:$F,$A10,Mesures!$C:$C,I$2),"") | ... DK10: =IFERROR(AVERAGEIFS(Mesures!$H:$H,Mesures!$F:$F,$A10,Mesures!$C:$C,DK$2),"")
A11: zoom 45 + frost 0.6 / sous les trusses | B11: =IFERROR(AVERAGEIFS(Mesures!$H:$H,Mesures!$F:$F,$A11,Mesures!$C:$C,B$2),"") | C11: =IFERROR(AVERAGEIFS(Mesures!$H:$H,Mesures!$F:$F,$A11,Mesures!$C:$C,C$2),"") | D11: =IFERROR(AVERAGEIFS(Mesures!$H:$H,Mesures!$F:$F,$A11,Mesures!$C:$C,D$2),"") | E11: =IFERROR(AVERAGEIFS(Mesures!$H:$H,Mesures!$F:$F,$A11,Mesures!$C:$C,E$2),"") | F11: =IFERROR(AVERAGEIFS(Mesures!$H:$H,Mesures!$F:$F,$A11,Mesures!$C:$C,F$2),"") | G11: =IFERROR(AVERAGEIFS(Mesures!$H:$H,Mesures!$F:$F,$A11,Mesures!$C:$C,G$2),"") | H11: =IFERROR(AVERAGEIFS(Mesures!$H:$H,Mesures!$F:$F,$A11,Mesures!$C:$C,H$2),"") | I11: =IFERROR(AVERAGEIFS(Mesures!$H:$H,Mesures!$F:$F,$A11,Mesures!$C:$C,I$2),"") | ... DK11: =IFERROR(AVERAGEIFS(Mesures!$H:$H,Mesures!$F:$F,$A11,Mesures!$C:$C,DK$2),"")
A12: sans rebonds (GI) | B12: =IFERROR(AVERAGEIFS(Mesures!$H:$H,Mesures!$F:$F,$A12,Mesures!$C:$C,B$2),"") | C12: =IFERROR(AVERAGEIFS(Mesures!$H:$H,Mesures!$F:$F,$A12,Mesures!$C:$C,C$2),"") | D12: =IFERROR(AVERAGEIFS(Mesures!$H:$H,Mesures!$F:$F,$A12,Mesures!$C:$C,D$2),"") | E12: =IFERROR(AVERAGEIFS(Mesures!$H:$H,Mesures!$F:$F,$A12,Mesures!$C:$C,E$2),"") | F12: =IFERROR(AVERAGEIFS(Mesures!$H:$H,Mesures!$F:$F,$A12,Mesures!$C:$C,F$2),"") | G12: =IFERROR(AVERAGEIFS(Mesures!$H:$H,Mesures!$F:$F,$A12,Mesures!$C:$C,G$2),"") | H12: =IFERROR(AVERAGEIFS(Mesures!$H:$H,Mesures!$F:$F,$A12,Mesures!$C:$C,H$2),"") | I12: =IFERROR(AVERAGEIFS(Mesures!$H:$H,Mesures!$F:$F,$A12,Mesures!$C:$C,I$2),"") | ... DK12: =IFERROR(AVERAGEIFS(Mesures!$H:$H,Mesures!$F:$F,$A12,Mesures!$C:$C,DK$2),"")
A13: sans fumee volumetrique | B13: =IFERROR(AVERAGEIFS(Mesures!$H:$H,Mesures!$F:$F,$A13,Mesures!$C:$C,B$2),"") | C13: =IFERROR(AVERAGEIFS(Mesures!$H:$H,Mesures!$F:$F,$A13,Mesures!$C:$C,C$2),"") | D13: =IFERROR(AVERAGEIFS(Mesures!$H:$H,Mesures!$F:$F,$A13,Mesures!$C:$C,D$2),"") | E13: =IFERROR(AVERAGEIFS(Mesures!$H:$H,Mesures!$F:$F,$A13,Mesures!$C:$C,E$2),"") | F13: =IFERROR(AVERAGEIFS(Mesures!$H:$H,Mesures!$F:$F,$A13,Mesures!$C:$C,F$2),"") | G13: =IFERROR(AVERAGEIFS(Mesures!$H:$H,Mesures!$F:$F,$A13,Mesures!$C:$C,G$2),"") | H13: =IFERROR(AVERAGEIFS(Mesures!$H:$H,Mesures!$F:$F,$A13,Mesures!$C:$C,H$2),"") | I13: =IFERROR(AVERAGEIFS(Mesures!$H:$H,Mesures!$F:$F,$A13,Mesures!$C:$C,I$2),"") | ... DK13: =IFERROR(AVERAGEIFS(Mesures!$H:$H,Mesures!$F:$F,$A13,Mesures!$C:$C,DK$2),"")
A14: sans taches sur surfaces | B14: =IFERROR(AVERAGEIFS(Mesures!$H:$H,Mesures!$F:$F,$A14,Mesures!$C:$C,B$2),"") | C14: =IFERROR(AVERAGEIFS(Mesures!$H:$H,Mesures!$F:$F,$A14,Mesures!$C:$C,C$2),"") | D14: =IFERROR(AVERAGEIFS(Mesures!$H:$H,Mesures!$F:$F,$A14,Mesures!$C:$C,D$2),"") | E14: =IFERROR(AVERAGEIFS(Mesures!$H:$H,Mesures!$F:$F,$A14,Mesures!$C:$C,E$2),"") | F14: =IFERROR(AVERAGEIFS(Mesures!$H:$H,Mesures!$F:$F,$A14,Mesures!$C:$C,F$2),"") | G14: =IFERROR(AVERAGEIFS(Mesures!$H:$H,Mesures!$F:$F,$A14,Mesures!$C:$C,G$2),"") | H14: =IFERROR(AVERAGEIFS(Mesures!$H:$H,Mesures!$F:$F,$A14,Mesures!$C:$C,H$2),"") | I14: =IFERROR(AVERAGEIFS(Mesures!$H:$H,Mesures!$F:$F,$A14,Mesures!$C:$C,I$2),"") | ... DK14: =IFERROR(AVERAGEIFS(Mesures!$H:$H,Mesures!$F:$F,$A14,Mesures!$C:$C,DK$2),"")
... A56: K4 Couronne zoom 45 / vers le point | B56: =IFERROR(AVERAGEIFS(Mesures!$H:$H,Mesures!$F:$F,$A56,Mesures!$C:$C,B$2),"") | C56: =IFERROR(AVERAGEIFS(Mesures!$H:$H,Mesures!$F:$F,$A56,Mesures!$C:$C,C$2),"") | D56: =IFERROR(AVERAGEIFS(Mesures!$H:$H,Mesures!$F:$F,$A56,Mesures!$C:$C,D$2),"") | E56: =IFERROR(AVERAGEIFS(Mesures!$H:$H,Mesures!$F:$F,$A56,Mesures!$C:$C,E$2),"") | F56: =IFERROR(AVERAGEIFS(Mesures!$H:$H,Mesures!$F:$F,$A56,Mesures!$C:$C,F$2),"") | G56: =IFERROR(AVERAGEIFS(Mesures!$H:$H,Mesures!$F:$F,$A56,Mesures!$C:$C,G$2),"") | H56: =IFERROR(AVERAGEIFS(Mesures!$H:$H,Mesures!$F:$F,$A56,Mesures!$C:$C,H$2),"") | I56: =IFERROR(AVERAGEIFS(Mesures!$H:$H,Mesures!$F:$F,$A56,Mesures!$C:$C,I$2),"") | ... DK56: =IFERROR(AVERAGEIFS(Mesures!$H:$H,Mesures!$F:$F,$A56,Mesures!$C:$C,DK$2),"")
A58: GPU moyen (ms)
A59: Cas | B59: 1. Reference avant sol texture | C59: 2. Sol beton texture (Concrete031) | D59: 3. Sol mouille 0,8 + reflet miroir | E59: 4. Faisceaux coupes aux obstacles + cube (banc rapide) | F59: 5a. Ombres coupees (shadows=0) | G59: 5b. Ombres des obstacles (shadows=1) | H59: 6a. Ombres + penombre : coupees (shadows=0) | I59: 6b. Ombres + penombre sur surfaces (shadows=1) | J59: 7a. Aberration chromatique codee, coupee (atlas R32F garde) | K59: 7b. Aberration chromatique coupee (banc rapide) | L59: 7c. Aberration chromatique active (banc rapide) | M59: 7e0. Essai v0 : aberration, enveloppe +2 %, chroma=1 | N59: 7e1. Essai v1 : enveloppe inchangee, flou par couleur, chroma=1 | O59: 7e3. Essai v3 : cache pour toutes les lyres, chroma=1 | P59: 7e4. Essai v4 : cache recalcule s'il change (RGBA16F), chroma=1 | Q59: 8. Longueur exacte des faisceaux arretes par le sol (bout des taches rasantes) | R59: 9a. Eau au sol : creux, flaques nettes, variante seche du shader | S59: 9b. Eau au sol a 10 % | T59: 9e. Essai : creux en trilineaire (abandonne) | U59: 10a. Reflet seulement dans l'eau (masque par blocs), eau 0,1 | V59: 10b. Reflet seulement dans l'eau, eau 0,3 | W59: 10c. Reflet seulement dans l'eau, eau 1 | X59: 10e1. Essai masque : 1 point par pixel du miroir (creux manques) | Y59: 10e3. Essai masque : faisceaux seulement dans les flaques (pores plus sombres) | Z59: 11. Lasers (prototype) : banc des lyres inchange | AA59: 11a. Lasers : triangles en addition (prototype) | AB59: 11b. Lasers : tuiles en calcul (prototype) | AC59: 12. Lasers : traits seuls (eventails de 16 traits au plus), nappe lisse allegee, triangles retires | AD59: 13a. Lasers, essai degrades v1 (meme shader, 6 vec4) | AE59: 13b. Lasers, essai degrades v2 (interpolation allegee) | AF59: 13c. Lasers, degrades : deux variantes du shader (gardee) | AG59: 13. Lasers : moteur et onglet Lasers (etape 2), formes, degrades, effets, boitiers, cas L7 | AH59: 14. Lasers : fumee de la piece (coupee, laserfog=0) | AI59: 14. Lasers : fumee de la piece (laserfog=1) | AJ59: 15. Lasers : diffusion avant 1 lobe (laserphase=0) | AK59: 15. Lasers : diffusion avant 2 lobes (laserphase=1) | AL59: 16. Lasers : volutes coupees (volutes=0) | AM59: 16. Lasers : volutes 1 octave (BC5 64^3, 1,6 m) | AN59: 17. Lasers : volutes, 2e octave coupee (volfine=0) | AO59: 17. Lasers : volutes, 2e octave de pres (volfine=1, portee -1) | AP59: 18. Lasers : variantes du shader, tout coupe (variante 0) | AQ59: 18. Lasers : variante 1 (fumee de la piece, 2 lobes) | AR59: 18. Lasers : variante 3 (+ volutes, 2 octaves) | AS59: 19. Lasers : etape 3 avant (reference) | AT59: 19. Lasers : etape 3 finale (fumee de la piece RG8, 2 lobes, volutes) | AU59: 19. Lyres : etape 3 finale (texture des amas RG8) | AV59: 20. Lasers : lecture ILDA, mode ligne, 16 384 segments | AW59: 20a. Essai ecarte : variante nappes et traits seuls (coupee) | AX59: 20a. Essai ecarte : variante nappes et traits seuls (active) | AY59: 20. Lyres : lecture ILDA (inchange) | AZ59: 21. Lasers : collisions, code present coupe (lasercoll=0) | BA59: 21. Lasers : collisions actives (essai, test avec branchement) | BB59: 22. Lasers : impacts coupes (laserimpacts=0) | BC59: 22. Lasers : impacts sur les surfaces | BD59: 22b. Lasers : etape 5 (collisions + impacts), en mouvement | BE59: 22b. Lyres : etape 5 (inchange) | BF59: 23. arcs : silhouettes adoucies, pyramide coupee a l'ecran et aux parois, passe des arcs a part | BG59: 24. Lasers : etape 9 (moteur de trace, arcs arretes sur les faces, formes par trace, plusieurs coeurs, cache des figures fixes) | BH59: 24. Lyres : etape 9 (inchange) | BI59: 25. Lasers : sorties sans traits parasites, blanchiment (camera) et lueur de sortie | BJ59: 25. Lyres : sorties et blanchiment des lasers (inchange) | BK59: 26. Lyres superposees a 1/4 (cases chargees) + diffus par direction des lyres douces + gobo ouvert sans lecture | BL59: 27. Lyres superposees a 1/4 seulement pour les grandes taches floues + scintillement du sol + variante legere des lyres frost | BM59: 28. AMD FSR 1 (EASU + RCAS), coupe par defaut | BN59: 29. Faisceaux 1/2 et 1/4 : flou a la taille d'un pixel de la fumee (plus de marches au bord des cones) | BO59: 30. Lasers : rendu photo (bords brillants 1, halo 0,1) + corrections des coupes | BP59: 30. Lasers : rendu photo, bords et halo coupes (laseredge=0, laserhalo=0) | BQ59: 30. Lyres : rendu photo des lasers (inchange) | BR59: 31. Lasers : convergence RGB 0,3 mrad + aberration objectif 0,2 % (avec le rendu photo) | BS59: 31. Lasers : convergence et objectif coupes (laserconv=0, laserlensca=0) | BT59: 31. Lyres : convergence RGB des lasers (inchange) | BU59: 32. Lasers : convergence RGB, un seul calcul pour les couleurs pures | BV59: 32. Lasers : L7 multicolore, rendu photo et convergence actifs | BW59: 32. Lasers : L7 multicolore, convergence et objectif coupes | BX59: 33. Fumee des lasers v2, etape 1 : texture des amas en RGBA8 (modele Classique) | BY59: 33. Fumee des lasers v2, etape 1 : modele Spatiale (carte seule, variante 1) | BZ59: 34. Fumee des lasers v2, etape 2 : nuages par erosion (variante 4) | CA59: 34. Fumee des lasers v2, etape 2 : sans les nuages (sferode=0, variante 1) | CB59: 34. Fumee des lasers v2, etape 2 : modele Classique (meme executable) | CC59: 34. Fumee des lasers v2, etape 2 : banc des lyres | CD59: 35. Fumee des lasers v2, etape 3 : tourbillons (3 sinus), sans filaments (variante 4) [INVALIDE : variante 2 du Classique mesuree (erreur corrigee), voir 37] | CE59: 35. Fumee des lasers v2, etape 3 : tourbillons et filaments de pres (variante 5 si un eventail passe pres) | CF59: 35. Fumee des lasers v2, etape 3 : modele Classique (bloc d'uniformes agrandi) | CG59: 36. Fumee des lasers v2, etape 4 : Classique (meme executable) | CH59: 36. Fumee des lasers v2, etape 4 : prereglage 3 Concert | CI59: 36. Fumee des lasers v2, etape 4 : prereglage 1 Hazer propre | CJ59: 36. Fumee des lasers v2, etape 4 : prereglage 5 Marbre de pres | CK59: 37. Fumee des lasers v2 : bancs seuilles par pixel, bords nuageux ; Classique (meme executable) | CL59: 37. Fumee des lasers v2 : bancs seuilles par pixel, bords nuageux ; Concert sans filaments (variante 4) | CM59: 37. Fumee des lasers v2 : bancs seuilles par pixel, bords nuageux ; Concert avec filaments (variante 5) | CN59: 38. Fumee des lasers v2 : salle composee ; Classique (meme executable) | CO59: 38. Fumee des lasers v2 : salle composee (sfpreset=6, filaments de l'utilisateur : force 1, 2 m, portee 1) | CP59: 38. Fumee des lasers v2 : salle composee sans filaments | CQ59: 39. Fumee des lasers v2 : salle composee en degrade (deux ambiances superposees) ; Classique (meme executable) | CR59: 39. Fumee des lasers v2 : salle composee en degrade (sfpreset=6, filaments de l'utilisateur) | CS59: 39. Fumee des lasers v2 : salle composee en degrade, sans filaments | CT59: 40. Spectacles laser (generateur de 30 scenes, 10 effets ajoutes) : banc des lasers inchange (avant -3,1 a +1,6 %, images identiques) | CU59: 41. Lasers : convergence RGB optimisee (traits en un calcul, impacts plafonnes, variante sans convergence, halo au quart, franges invisibles sautees, impacts des arcs) | CV59: 41. Lasers : convergence et objectif coupes (meme executable) | CW59: 42. Lasers : impacts en quadrilatere exact (au lieu de carres de marge) + bords des nappes par couleur seulement pres du bord | CX59: 43. Optim. lasers etape 1 : journal par image (fumee CPU, Present) et compteurs de mesure (--stats) ; image et shaders inchanges | CY59: 44. Optim. lasers etape 2 : fumee CPU en tache de fond (3 coeurs) ; presentation avec dechirure (bancs : 2 tampons, spectacle : 3 tampons, latence 2) | CZ59: 45. Optim. lasers etape 3 : passes de fumee des lyres sautees sans lyre allumee (0.9) ; 0.3 et 0.4 essayes, sans gain, retires | DA59: 46. Optim. lasers etape 4 (essai, non garde) : lumiere lente interpolee par tuile sur les nappes planes, tolerance 2 % | DB59: 47. Optim. lasers etape 5 : morceaux voisins d'un meme cercle fusionnes (cones : 2 morceaux par cercle au lieu de 4) | DC59: 48. Optim. lasers etape 7 : resolution adaptative des lasers (80, 70, 50 % sous 60 img/s), agrandissement selon la profondeur | DD59: 49. Impacts des arcs : decoupage par face en tranches de 22,5 deg (traits au sol qui clignotaient) | DE59: 50. Impacts : largeur minimale comptee a l'ecran (traits au sol en pointilles au loin), laserhitmin=0 | DF59: 50. Impacts : largeur minimale comptee a l'ecran (traits au sol en pointilles au loin), laserhitmin=1 | DG59: 51. Lumiere des lasers dans la piece (VPL dans les sondes), lasergi=0 | DH59: 51. Lumiere des lasers dans la piece (VPL dans les sondes), lasergi=1 | DI59: 51. Lumiere des lasers dans la piece : banc des lyres (lasergi=0 par defaut) | DJ59: 52. Reflets du sol mouille : lasers dans le reflet, beton mouille flou, flou des flaques | DK59: 52. Reflets du sol mouille : banc des lasers
A60: defaut / public | B60: =IFERROR(AVERAGEIFS(Mesures!$I:$I,Mesures!$F:$F,$A60,Mesures!$C:$C,B$59),"") | C60: =IFERROR(AVERAGEIFS(Mesures!$I:$I,Mesures!$F:$F,$A60,Mesures!$C:$C,C$59),"") | D60: =IFERROR(AVERAGEIFS(Mesures!$I:$I,Mesures!$F:$F,$A60,Mesures!$C:$C,D$59),"") | E60: =IFERROR(AVERAGEIFS(Mesures!$I:$I,Mesures!$F:$F,$A60,Mesures!$C:$C,E$59),"") | F60: =IFERROR(AVERAGEIFS(Mesures!$I:$I,Mesures!$F:$F,$A60,Mesures!$C:$C,F$59),"") | G60: =IFERROR(AVERAGEIFS(Mesures!$I:$I,Mesures!$F:$F,$A60,Mesures!$C:$C,G$59),"") | H60: =IFERROR(AVERAGEIFS(Mesures!$I:$I,Mesures!$F:$F,$A60,Mesures!$C:$C,H$59),"") | I60: =IFERROR(AVERAGEIFS(Mesures!$I:$I,Mesures!$F:$F,$A60,Mesures!$C:$C,I$59),"") | ... DK60: =IFERROR(AVERAGEIFS(Mesures!$I:$I,Mesures!$F:$F,$A60,Mesures!$C:$C,DK$59),"")
A61: defaut / scene | B61: =IFERROR(AVERAGEIFS(Mesures!$I:$I,Mesures!$F:$F,$A61,Mesures!$C:$C,B$59),"") | C61: =IFERROR(AVERAGEIFS(Mesures!$I:$I,Mesures!$F:$F,$A61,Mesures!$C:$C,C$59),"") | D61: =IFERROR(AVERAGEIFS(Mesures!$I:$I,Mesures!$F:$F,$A61,Mesures!$C:$C,D$59),"") | E61: =IFERROR(AVERAGEIFS(Mesures!$I:$I,Mesures!$F:$F,$A61,Mesures!$C:$C,E$59),"") | F61: =IFERROR(AVERAGEIFS(Mesures!$I:$I,Mesures!$F:$F,$A61,Mesures!$C:$C,F$59),"") | G61: =IFERROR(AVERAGEIFS(Mesures!$I:$I,Mesures!$F:$F,$A61,Mesures!$C:$C,G$59),"") | H61: =IFERROR(AVERAGEIFS(Mesures!$I:$I,Mesures!$F:$F,$A61,Mesures!$C:$C,H$59),"") | I61: =IFERROR(AVERAGEIFS(Mesures!$I:$I,Mesures!$F:$F,$A61,Mesures!$C:$C,I$59),"") | ... DK61: =IFERROR(AVERAGEIFS(Mesures!$I:$I,Mesures!$F:$F,$A61,Mesures!$C:$C,DK$59),"")
A62: defaut / sous les trusses | B62: =IFERROR(AVERAGEIFS(Mesures!$I:$I,Mesures!$F:$F,$A62,Mesures!$C:$C,B$59),"") | C62: =IFERROR(AVERAGEIFS(Mesures!$I:$I,Mesures!$F:$F,$A62,Mesures!$C:$C,C$59),"") | D62: =IFERROR(AVERAGEIFS(Mesures!$I:$I,Mesures!$F:$F,$A62,Mesures!$C:$C,D$59),"") | E62: =IFERROR(AVERAGEIFS(Mesures!$I:$I,Mesures!$F:$F,$A62,Mesures!$C:$C,E$59),"") | F62: =IFERROR(AVERAGEIFS(Mesures!$I:$I,Mesures!$F:$F,$A62,Mesures!$C:$C,F$59),"") | G62: =IFERROR(AVERAGEIFS(Mesures!$I:$I,Mesures!$F:$F,$A62,Mesures!$C:$C,G$59),"") | H62: =IFERROR(AVERAGEIFS(Mesures!$I:$I,Mesures!$F:$F,$A62,Mesures!$C:$C,H$59),"") | I62: =IFERROR(AVERAGEIFS(Mesures!$I:$I,Mesures!$F:$F,$A62,Mesures!$C:$C,I$59),"") | ... DK62: =IFERROR(AVERAGEIFS(Mesures!$I:$I,Mesures!$F:$F,$A62,Mesures!$C:$C,DK$59),"")
A63: gobo + prisme 8 + zoom 25 / public | B63: =IFERROR(AVERAGEIFS(Mesures!$I:$I,Mesures!$F:$F,$A63,Mesures!$C:$C,B$59),"") | C63: =IFERROR(AVERAGEIFS(Mesures!$I:$I,Mesures!$F:$F,$A63,Mesures!$C:$C,C$59),"") | D63: =IFERROR(AVERAGEIFS(Mesures!$I:$I,Mesures!$F:$F,$A63,Mesures!$C:$C,D$59),"") | E63: =IFERROR(AVERAGEIFS(Mesures!$I:$I,Mesures!$F:$F,$A63,Mesures!$C:$C,E$59),"") | F63: =IFERROR(AVERAGEIFS(Mesures!$I:$I,Mesures!$F:$F,$A63,Mesures!$C:$C,F$59),"") | G63: =IFERROR(AVERAGEIFS(Mesures!$I:$I,Mesures!$F:$F,$A63,Mesures!$C:$C,G$59),"") | H63: =IFERROR(AVERAGEIFS(Mesures!$I:$I,Mesures!$F:$F,$A63,Mesures!$C:$C,H$59),"") | I63: =IFERROR(AVERAGEIFS(Mesures!$I:$I,Mesures!$F:$F,$A63,Mesures!$C:$C,I$59),"") | ... DK63: =IFERROR(AVERAGEIFS(Mesures!$I:$I,Mesures!$F:$F,$A63,Mesures!$C:$C,DK$59),"")
A64: gobo + prisme 8 + zoom 25 / scene | B64: =IFERROR(AVERAGEIFS(Mesures!$I:$I,Mesures!$F:$F,$A64,Mesures!$C:$C,B$59),"") | C64: =IFERROR(AVERAGEIFS(Mesures!$I:$I,Mesures!$F:$F,$A64,Mesures!$C:$C,C$59),"") | D64: =IFERROR(AVERAGEIFS(Mesures!$I:$I,Mesures!$F:$F,$A64,Mesures!$C:$C,D$59),"") | E64: =IFERROR(AVERAGEIFS(Mesures!$I:$I,Mesures!$F:$F,$A64,Mesures!$C:$C,E$59),"") | F64: =IFERROR(AVERAGEIFS(Mesures!$I:$I,Mesures!$F:$F,$A64,Mesures!$C:$C,F$59),"") | G64: =IFERROR(AVERAGEIFS(Mesures!$I:$I,Mesures!$F:$F,$A64,Mesures!$C:$C,G$59),"") | H64: =IFERROR(AVERAGEIFS(Mesures!$I:$I,Mesures!$F:$F,$A64,Mesures!$C:$C,H$59),"") | I64: =IFERROR(AVERAGEIFS(Mesures!$I:$I,Mesures!$F:$F,$A64,Mesures!$C:$C,I$59),"") | ... DK64: =IFERROR(AVERAGEIFS(Mesures!$I:$I,Mesures!$F:$F,$A64,Mesures!$C:$C,DK$59),"")
A65: gobo + prisme 8 + zoom 25 / sous les trusses | B65: =IFERROR(AVERAGEIFS(Mesures!$I:$I,Mesures!$F:$F,$A65,Mesures!$C:$C,B$59),"") | C65: =IFERROR(AVERAGEIFS(Mesures!$I:$I,Mesures!$F:$F,$A65,Mesures!$C:$C,C$59),"") | D65: =IFERROR(AVERAGEIFS(Mesures!$I:$I,Mesures!$F:$F,$A65,Mesures!$C:$C,D$59),"") | E65: =IFERROR(AVERAGEIFS(Mesures!$I:$I,Mesures!$F:$F,$A65,Mesures!$C:$C,E$59),"") | F65: =IFERROR(AVERAGEIFS(Mesures!$I:$I,Mesures!$F:$F,$A65,Mesures!$C:$C,F$59),"") | G65: =IFERROR(AVERAGEIFS(Mesures!$I:$I,Mesures!$F:$F,$A65,Mesures!$C:$C,G$59),"") | H65: =IFERROR(AVERAGEIFS(Mesures!$I:$I,Mesures!$F:$F,$A65,Mesures!$C:$C,H$59),"") | I65: =IFERROR(AVERAGEIFS(Mesures!$I:$I,Mesures!$F:$F,$A65,Mesures!$C:$C,I$59),"") | ... DK65: =IFERROR(AVERAGEIFS(Mesures!$I:$I,Mesures!$F:$F,$A65,Mesures!$C:$C,DK$59),"")
A66: zoom 45 + frost 0.6 / public | B66: =IFERROR(AVERAGEIFS(Mesures!$I:$I,Mesures!$F:$F,$A66,Mesures!$C:$C,B$59),"") | C66: =IFERROR(AVERAGEIFS(Mesures!$I:$I,Mesures!$F:$F,$A66,Mesures!$C:$C,C$59),"") | D66: =IFERROR(AVERAGEIFS(Mesures!$I:$I,Mesures!$F:$F,$A66,Mesures!$C:$C,D$59),"") | E66: =IFERROR(AVERAGEIFS(Mesures!$I:$I,Mesures!$F:$F,$A66,Mesures!$C:$C,E$59),"") | F66: =IFERROR(AVERAGEIFS(Mesures!$I:$I,Mesures!$F:$F,$A66,Mesures!$C:$C,F$59),"") | G66: =IFERROR(AVERAGEIFS(Mesures!$I:$I,Mesures!$F:$F,$A66,Mesures!$C:$C,G$59),"") | H66: =IFERROR(AVERAGEIFS(Mesures!$I:$I,Mesures!$F:$F,$A66,Mesures!$C:$C,H$59),"") | I66: =IFERROR(AVERAGEIFS(Mesures!$I:$I,Mesures!$F:$F,$A66,Mesures!$C:$C,I$59),"") | ... DK66: =IFERROR(AVERAGEIFS(Mesures!$I:$I,Mesures!$F:$F,$A66,Mesures!$C:$C,DK$59),"")
A67: zoom 45 + frost 0.6 / scene | B67: =IFERROR(AVERAGEIFS(Mesures!$I:$I,Mesures!$F:$F,$A67,Mesures!$C:$C,B$59),"") | C67: =IFERROR(AVERAGEIFS(Mesures!$I:$I,Mesures!$F:$F,$A67,Mesures!$C:$C,C$59),"") | D67: =IFERROR(AVERAGEIFS(Mesures!$I:$I,Mesures!$F:$F,$A67,Mesures!$C:$C,D$59),"") | E67: =IFERROR(AVERAGEIFS(Mesures!$I:$I,Mesures!$F:$F,$A67,Mesures!$C:$C,E$59),"") | F67: =IFERROR(AVERAGEIFS(Mesures!$I:$I,Mesures!$F:$F,$A67,Mesures!$C:$C,F$59),"") | G67: =IFERROR(AVERAGEIFS(Mesures!$I:$I,Mesures!$F:$F,$A67,Mesures!$C:$C,G$59),"") | H67: =IFERROR(AVERAGEIFS(Mesures!$I:$I,Mesures!$F:$F,$A67,Mesures!$C:$C,H$59),"") | I67: =IFERROR(AVERAGEIFS(Mesures!$I:$I,Mesures!$F:$F,$A67,Mesures!$C:$C,I$59),"") | ... DK67: =IFERROR(AVERAGEIFS(Mesures!$I:$I,Mesures!$F:$F,$A67,Mesures!$C:$C,DK$59),"")
A68: zoom 45 + frost 0.6 / sous les trusses | B68: =IFERROR(AVERAGEIFS(Mesures!$I:$I,Mesures!$F:$F,$A68,Mesures!$C:$C,B$59),"") | C68: =IFERROR(AVERAGEIFS(Mesures!$I:$I,Mesures!$F:$F,$A68,Mesures!$C:$C,C$59),"") | D68: =IFERROR(AVERAGEIFS(Mesures!$I:$I,Mesures!$F:$F,$A68,Mesures!$C:$C,D$59),"") | E68: =IFERROR(AVERAGEIFS(Mesures!$I:$I,Mesures!$F:$F,$A68,Mesures!$C:$C,E$59),"") | F68: =IFERROR(AVERAGEIFS(Mesures!$I:$I,Mesures!$F:$F,$A68,Mesures!$C:$C,F$59),"") | G68: =IFERROR(AVERAGEIFS(Mesures!$I:$I,Mesures!$F:$F,$A68,Mesures!$C:$C,G$59),"") | H68: =IFERROR(AVERAGEIFS(Mesures!$I:$I,Mesures!$F:$F,$A68,Mesures!$C:$C,H$59),"") | I68: =IFERROR(AVERAGEIFS(Mesures!$I:$I,Mesures!$F:$F,$A68,Mesures!$C:$C,I$59),"") | ... DK68: =IFERROR(AVERAGEIFS(Mesures!$I:$I,Mesures!$F:$F,$A68,Mesures!$C:$C,DK$59),"")
A69: sans rebonds (GI) | B69: =IFERROR(AVERAGEIFS(Mesures!$I:$I,Mesures!$F:$F,$A69,Mesures!$C:$C,B$59),"") | C69: =IFERROR(AVERAGEIFS(Mesures!$I:$I,Mesures!$F:$F,$A69,Mesures!$C:$C,C$59),"") | D69: =IFERROR(AVERAGEIFS(Mesures!$I:$I,Mesures!$F:$F,$A69,Mesures!$C:$C,D$59),"") | E69: =IFERROR(AVERAGEIFS(Mesures!$I:$I,Mesures!$F:$F,$A69,Mesures!$C:$C,E$59),"") | F69: =IFERROR(AVERAGEIFS(Mesures!$I:$I,Mesures!$F:$F,$A69,Mesures!$C:$C,F$59),"") | G69: =IFERROR(AVERAGEIFS(Mesures!$I:$I,Mesures!$F:$F,$A69,Mesures!$C:$C,G$59),"") | H69: =IFERROR(AVERAGEIFS(Mesures!$I:$I,Mesures!$F:$F,$A69,Mesures!$C:$C,H$59),"") | I69: =IFERROR(AVERAGEIFS(Mesures!$I:$I,Mesures!$F:$F,$A69,Mesures!$C:$C,I$59),"") | ... DK69: =IFERROR(AVERAGEIFS(Mesures!$I:$I,Mesures!$F:$F,$A69,Mesures!$C:$C,DK$59),"")
A70: sans fumee volumetrique | B70: =IFERROR(AVERAGEIFS(Mesures!$I:$I,Mesures!$F:$F,$A70,Mesures!$C:$C,B$59),"") | C70: =IFERROR(AVERAGEIFS(Mesures!$I:$I,Mesures!$F:$F,$A70,Mesures!$C:$C,C$59),"") | D70: =IFERROR(AVERAGEIFS(Mesures!$I:$I,Mesures!$F:$F,$A70,Mesures!$C:$C,D$59),"") | E70: =IFERROR(AVERAGEIFS(Mesures!$I:$I,Mesures!$F:$F,$A70,Mesures!$C:$C,E$59),"") | F70: =IFERROR(AVERAGEIFS(Mesures!$I:$I,Mesures!$F:$F,$A70,Mesures!$C:$C,F$59),"") | G70: =IFERROR(AVERAGEIFS(Mesures!$I:$I,Mesures!$F:$F,$A70,Mesures!$C:$C,G$59),"") | H70: =IFERROR(AVERAGEIFS(Mesures!$I:$I,Mesures!$F:$F,$A70,Mesures!$C:$C,H$59),"") | I70: =IFERROR(AVERAGEIFS(Mesures!$I:$I,Mesures!$F:$F,$A70,Mesures!$C:$C,I$59),"") | ... DK70: =IFERROR(AVERAGEIFS(Mesures!$I:$I,Mesures!$F:$F,$A70,Mesures!$C:$C,DK$59),"")
A71: sans taches sur surfaces | B71: =IFERROR(AVERAGEIFS(Mesures!$I:$I,Mesures!$F:$F,$A71,Mesures!$C:$C,B$59),"") | C71: =IFERROR(AVERAGEIFS(Mesures!$I:$I,Mesures!$F:$F,$A71,Mesures!$C:$C,C$59),"") | D71: =IFERROR(AVERAGEIFS(Mesures!$I:$I,Mesures!$F:$F,$A71,Mesures!$C:$C,D$59),"") | E71: =IFERROR(AVERAGEIFS(Mesures!$I:$I,Mesures!$F:$F,$A71,Mesures!$C:$C,E$59),"") | F71: =IFERROR(AVERAGEIFS(Mesures!$I:$I,Mesures!$F:$F,$A71,Mesures!$C:$C,F$59),"") | G71: =IFERROR(AVERAGEIFS(Mesures!$I:$I,Mesures!$F:$F,$A71,Mesures!$C:$C,G$59),"") | H71: =IFERROR(AVERAGEIFS(Mesures!$I:$I,Mesures!$F:$F,$A71,Mesures!$C:$C,H$59),"") | I71: =IFERROR(AVERAGEIFS(Mesures!$I:$I,Mesures!$F:$F,$A71,Mesures!$C:$C,I$59),"") | ... DK71: =IFERROR(AVERAGEIFS(Mesures!$I:$I,Mesures!$F:$F,$A71,Mesures!$C:$C,DK$59),"")
... A113: K4 Couronne zoom 45 / vers le point | B113: =IFERROR(AVERAGEIFS(Mesures!$I:$I,Mesures!$F:$F,$A113,Mesures!$C:$C,B$59),"") | C113: =IFERROR(AVERAGEIFS(Mesures!$I:$I,Mesures!$F:$F,$A113,Mesures!$C:$C,C$59),"") | D113: =IFERROR(AVERAGEIFS(Mesures!$I:$I,Mesures!$F:$F,$A113,Mesures!$C:$C,D$59),"") | E113: =IFERROR(AVERAGEIFS(Mesures!$I:$I,Mesures!$F:$F,$A113,Mesures!$C:$C,E$59),"") | F113: =IFERROR(AVERAGEIFS(Mesures!$I:$I,Mesures!$F:$F,$A113,Mesures!$C:$C,F$59),"") | G113: =IFERROR(AVERAGEIFS(Mesures!$I:$I,Mesures!$F:$F,$A113,Mesures!$C:$C,G$59),"") | H113: =IFERROR(AVERAGEIFS(Mesures!$I:$I,Mesures!$F:$F,$A113,Mesures!$C:$C,H$59),"") | I113: =IFERROR(AVERAGEIFS(Mesures!$I:$I,Mesures!$F:$F,$A113,Mesures!$C:$C,I$59),"") | ... DK113: =IFERROR(AVERAGEIFS(Mesures!$I:$I,Mesures!$F:$F,$A113,Mesures!$C:$C,DK$59),"")

Sheet Lisez-moi
A1: Historique des performances de LyreViz (GTX 1080, 3840 x 2160, 200 lyres)
A3: Une ligne de 'Mesures' par cas du banc d'essai et par modification. On ajoute, on ne modifie pas.
A4: Ajout : python tools\historique.py --modif "nom" --reglages "..." bench\dossier1 bench\dossier2
A5: plusieurs dossiers = lancements de la meme version et des memes reglages, moyennes.
A6: 'Comparaison' : un cas par ligne, une modification par colonne (formules sur 'Mesures').
A8: Colonnes :
A9: Image (ms) : duree moyenne d'une image (= img/s reelles, presentation comprise).
A10: GPU moyen / mediane : temps GPU total d'une image.
A11: Surfaces : passe des surfaces + lyres douces. Fumee : toutes les passes de fumee. Reflet sol : passe miroir.
A12: Paires d'ombre : paires (lyre, obstacle) de l'ombre (vide avant les ombres).
A14: A comparer seulement entre lignes aux memes reglages (qualite adaptative, mouvement / immobile).
A15: Les temps varient de 10 a 20 % d'un lancement a l'autre : voir PERFORMANCE.md.
A16: Objectif : 8,3 ms par image (120 img/s).
